(entorno_jevg) ttm@raspberrypi:~/TT2_Photovoltaic_Roof_Cleaner $ sudo /home/ttm/TT2_Photovoltaic_Roof_Cleaner/entorno_jevg/bin/python /home/ttm/TT2_Photovoltaic_Roof_Cleaner/SistemaControlComunicacion/main.py
Traceback (most recent call last):
  File "/home/ttm/TT2_Photovoltaic_Roof_Cleaner/entorno_jevg/lib/python3.11/site-packages/gpiozero/pins/pi.py", line 411, in pin
    pin = self.pins[info]
          ~~~~~~~~~^^^^^^
KeyError: PinInfo(number=16, name='GPIO23', names=frozenset({'J8:16', 'BCM23', 'GPIO23', 'BOARD16', 23, 'WPI4', '23'}), pull='', row=8, col=2, interfaces=frozenset({'sdio', '', 'dpi', 'jtag', 'i2c', 'gpio'}))

During handling of the above exception, another exception occurred:

Traceback (most recent call last):
  File "/home/ttm/TT2_Photovoltaic_Roof_Cleaner/SistemaControlComunicacion/main.py", line 3, in <module>
    import callbacks
  File "/home/ttm/TT2_Photovoltaic_Roof_Cleaner/SistemaControlComunicacion/callbacks.py", line 2, in <module>
    from functions import move_forward, move_backward, move_left, move_right, rotate_right, rotate_left
  File "/home/ttm/TT2_Photovoltaic_Roof_Cleaner/SistemaControlComunicacion/functions.py", line 51, in <module>
    motor1 = StepperMotor(23, 24, 25)
             ^^^^^^^^^^^^^^^^^^^^^^^^
  File "/home/ttm/TT2_Photovoltaic_Roof_Cleaner/SistemaControlComunicacion/functions.py", line 23, in __init__
    self.PUL = OutputDevice(pul_pin)
               ^^^^^^^^^^^^^^^^^^^^^
  File "/home/ttm/TT2_Photovoltaic_Roof_Cleaner/entorno_jevg/lib/python3.11/site-packages/gpiozero/devices.py", line 108, in __call__
    self = super().__call__(*args, **kwargs)
           ^^^^^^^^^^^^^^^^^^^^^^^^^^^^^^^^^
  File "/home/ttm/TT2_Photovoltaic_Roof_Cleaner/entorno_jevg/lib/python3.11/site-packages/gpiozero/output_devices.py", line 74, in __init__
    super().__init__(pin, pin_factory=pin_factory)
  File "/home/ttm/TT2_Photovoltaic_Roof_Cleaner/entorno_jevg/lib/python3.11/site-packages/gpiozero/mixins.py", line 75, in __init__
    super().__init__(*args, **kwargs)
  File "/home/ttm/TT2_Photovoltaic_Roof_Cleaner/entorno_jevg/lib/python3.11/site-packages/gpiozero/devices.py", line 553, in __init__
    pin = self.pin_factory.pin(pin)
          ^^^^^^^^^^^^^^^^^^^^^^^^^
  File "/home/ttm/TT2_Photovoltaic_Roof_Cleaner/entorno_jevg/lib/python3.11/site-packages/gpiozero/pins/pi.py", line 413, in pin
    pin = self.pin_class(self, info)
          ^^^^^^^^^^^^^^^^^^^^^^^^^^
  File "/home/ttm/TT2_Photovoltaic_Roof_Cleaner/entorno_jevg/lib/python3.11/site-packages/gpiozero/pins/rpigpio.py", line 101, in __init__
    GPIO.setup(self._number, GPIO.IN, self.GPIO_PULL_UPS[self._pull])
RuntimeError: Cannot determine SOC peripheral base address